<?xml version="1.0" encoding="utf-8"?>
<!-- This URDF was automatically created by SolidWorks to URDF Exporter! Originally created by Stephen Brawner (brawner@gmail.com) 
     Commit Version: 1.5.1-0-g916b5db  Build Version: 1.5.7152.31018
     For more information, please see http://wiki.ros.org/sw_urdf_exporter -->
<robot
  name="lidarcam">
  <link
    name="base_link">
    <inertial>
      <origin
        xyz="0.108922864318345 0.123403521783607 0.0847241760555164"
        rpy="0 0 0" />
      <mass
        value="3.90118326560913" />
      <inertia
        ixx="0.0186236720310461"
        ixy="1.46573682202297E-06"
        ixz="-3.31789538677575E-07"
        iyy="0.00875282674130426"
        iyz="8.06514530952676E-06"
        izz="0.0179160741187242" />
    </inertial>
    <visual>
      <origin
        xyz="0 0 0"
        rpy="0 0 0" />
      <geometry>
        <mesh
          filename="package://lidarcam/meshes/base_link.STL" />
      </geometry>
      <material
        name="">
        <color
          rgba="0.752941176470588 0.752941176470588 0.752941176470588 1" />
      </material>
    </visual>
    <collision>
      <origin
        xyz="0 0 0"
        rpy="0 0 0" />
      <geometry>
        <mesh
          filename="package://lidarcam/meshes/base_link.STL" />
      </geometry>
    </collision>
  </link>
  <link
    name="LFS">
    <inertial>
      <origin
        xyz="-0.0156936568910528 0.0174176382369257 0.00735669197046052"
        rpy="0 0 0" />
      <mass
        value="0.26437001106024" />
      <inertia
        ixx="6.29151972289897E-05"
        ixy="2.96411876511101E-09"
        ixz="1.6484530205674E-08"
        iyy="6.2207209100296E-05"
        iyz="1.56454773175247E-07"
        izz="3.20746276473134E-05" />
    </inertial>
    <visual>
      <origin
        xyz="0 0 0"
        rpy="0 0 0" />
      <geometry>
        <mesh
          filename="package://lidarcam/meshes/LFS.STL" />
      </geometry>
      <material
        name="">
        <color
          rgba="0.752941176470588 0.752941176470588 0.752941176470588 1" />
      </material>
    </visual>
    <collision>
      <origin
        xyz="0 0 0"
        rpy="0 0 0" />
      <geometry>
        <mesh
          filename="package://lidarcam/meshes/LFS.STL" />
      </geometry>
    </collision>
  </link>
  <joint
    name="LFS"
    type="prismatic">
    <origin
      xyz="0.24112 0.018826 0"
      rpy="0 1.5708 0" />
    <parent
      link="base_link" />
    <child
      link="LFS" />
    <axis
      xyz="1 0 0" />
    <limit
      lower="0"
      upper="0"
      effort="0"
      velocity="0" />
  </joint>
  <link
    name="LFW">
    <inertial>
      <origin
        xyz="0.0150000000000001 1.73472347597681E-18 -3.46944695195361E-18"
        rpy="0 0 0" />
      <mass
        value="0.239316435984071" />
      <inertia
        ixx="0.00030040943490763"
        ixy="-7.49377648649208E-37"
        ixz="-1.53291517986879E-38"
        iyy="0.00016815345015262"
        iyz="-1.54101050386111E-36"
        izz="0.00016815345015262" />
    </inertial>
    <visual>
      <origin
        xyz="0 0 0"
        rpy="0 0 0" />
      <geometry>
        <mesh
          filename="package://lidarcam/meshes/LFW.STL" />
      </geometry>
      <material
        name="">
        <color
          rgba="1 1 1 1" />
      </material>
    </visual>
    <collision>
      <origin
        xyz="0 0 0"
        rpy="0 0 0" />
      <geometry>
        <mesh
          filename="package://lidarcam/meshes/LFW.STL" />
      </geometry>
    </collision>
  </link>
  <joint
    name="LFW"
    type="continuous">
    <origin
      xyz="0.014801 0.0046744 0.050633"
      rpy="1.5708 -1.5708 0" />
    <parent
      link="LFS" />
    <child
      link="LFW" />
    <axis
      xyz="1 0 0" />
    <limit
      effort="3.1"
      velocity="7" />
  </joint>
  <link
    name="RFS">
    <inertial>
      <origin
        xyz="-0.0156849499498769 0.0179312188717306 0.00735669197046058"
        rpy="0 0 0" />
      <mass
        value="0.26437001106024" />
      <inertia
        ixx="6.29151972289897E-05"
        ixy="2.9641187651092E-09"
        ixz="-1.64845302056385E-08"
        iyy="6.2207209100296E-05"
        iyz="-1.56454773175214E-07"
        izz="3.20746276473134E-05" />
    </inertial>
    <visual>
      <origin
        xyz="0 0 0"
        rpy="0 0 0" />
      <geometry>
        <mesh
          filename="package://lidarcam/meshes/RFS.STL" />
      </geometry>
      <material
        name="">
        <color
          rgba="0.752941176470588 0.752941176470588 0.752941176470588 1" />
      </material>
    </visual>
    <collision>
      <origin
        xyz="0 0 0"
        rpy="0 0 0" />
      <geometry>
        <mesh
          filename="package://lidarcam/meshes/RFS.STL" />
      </geometry>
    </collision>
  </link>
  <joint
    name="RFS"
    type="prismatic">
    <origin
      xyz="-0.025117 0.054174 0"
      rpy="3.1416 1.5708 0" />
    <parent
      link="base_link" />
    <child
      link="RFS" />
    <axis
      xyz="1 0 0" />
    <limit
      lower="0"
      upper="0"
      effort="0"
      velocity="0" />
  </joint>
  <link
    name="RFW">
    <inertial>
      <origin
        xyz="-0.015 6.76542155630955E-17 4.85722573273506E-17"
        rpy="0 0 0" />
      <mass
        value="0.239316435984071" />
      <inertia
        ixx="0.000300409434907629"
        ixy="-2.68087886495849E-37"
        ixz="7.53542435711164E-37"
        iyy="0.00016815345015262"
        iyz="-1.6940658945086E-21"
        izz="0.00016815345015262" />
    </inertial>
    <visual>
      <origin
        xyz="0 0 0"
        rpy="0 0 0" />
      <geometry>
        <mesh
          filename="package://lidarcam/meshes/RFW.STL" />
      </geometry>
      <material
        name="">
        <color
          rgba="1 1 1 1" />
      </material>
    </visual>
    <collision>
      <origin
        xyz="0 0 0"
        rpy="0 0 0" />
      <geometry>
        <mesh
          filename="package://lidarcam/meshes/RFW.STL" />
      </geometry>
    </collision>
  </link>
  <joint
    name="RFW"
    type="continuous">
    <origin
      xyz="0.014799 0.030674 0.050633"
      rpy="1.64 1.5708 0" />
    <parent
      link="RFS" />
    <child
      link="RFW" />
    <axis
      xyz="1 0 0" />
    <limit
      effort="3.1"
      velocity="7" />
  </joint>
  <link
    name="LBS">
    <inertial>
      <origin
        xyz="0.00234157571377286 0.0116051947593446 0.0030324510222364"
        rpy="0 0 0" />
      <mass
        value="0.18193357253929" />
      <inertia
        ixx="0.000158415198867683"
        ixy="3.54095934938036E-07"
        ixz="-1.51072226729719E-20"
        iyy="0.000187903911280684"
        iyz="-4.24859260985408E-20"
        izz="0.000106956315729353" />
    </inertial>
    <visual>
      <origin
        xyz="0 0 0"
        rpy="0 0 0" />
      <geometry>
        <mesh
          filename="package://lidarcam/meshes/LBS.STL" />
      </geometry>
      <material
        name="">
        <color
          rgba="0.752941176470588 0.752941176470588 0.752941176470588 1" />
      </material>
    </visual>
    <collision>
      <origin
        xyz="0 0 0"
        rpy="0 0 0" />
      <geometry>
        <mesh
          filename="package://lidarcam/meshes/LBS.STL" />
      </geometry>
    </collision>
  </link>
  <joint
    name="LBS"
    type="prismatic">
    <origin
      xyz="0.28235 0.22575 0"
      rpy="3.1416 0 0" />
    <parent
      link="base_link" />
    <child
      link="LBS" />
    <axis
      xyz="0 0 1" />
    <limit
      lower="0"
      upper="0"
      effort="0"
      velocity="0" />
  </joint>
  <link
    name="RBS">
    <inertial>
      <origin
        xyz="0.00234157571377329 0.0116051947593451 0.0030324510222366"
        rpy="0 0 0" />
      <mass
        value="0.18193357253929" />
      <inertia
        ixx="0.000158415198867683"
        ixy="3.54095934938048E-07"
        ixz="1.49383303884476E-21"
        iyy="0.000187903911280684"
        iyz="-7.51531864264989E-21"
        izz="0.000106956315729353" />
    </inertial>
    <visual>
      <origin
        xyz="0 0 0"
        rpy="0 0 0" />
      <geometry>
        <mesh
          filename="package://lidarcam/meshes/RBS.STL" />
      </geometry>
      <material
        name="">
        <color
          rgba="0.752941176470588 0.752941176470588 0.752941176470588 1" />
      </material>
    </visual>
    <collision>
      <origin
        xyz="0 0 0"
        rpy="0 0 0" />
      <geometry>
        <mesh
          filename="package://lidarcam/meshes/RBS.STL" />
      </geometry>
    </collision>
  </link>
  <joint
    name="RBS"
    type="prismatic">
    <origin
      xyz="-0.06635 0.20125 0"
      rpy="3.1416 0 3.1416" />
    <parent
      link="base_link" />
    <child
      link="RBS" />
    <axis
      xyz="0 0 1" />
    <limit
      lower="0"
      upper="0"
      effort="0"
      velocity="0" />
  </joint>
  <link
    name="fcam">
    <inertial>
      <origin
        xyz="0.000445525090231174 -1.10631679103579E-05 0.00129821973144106"
        rpy="0 0 0" />
      <mass
        value="0.0436119950287128" />
      <inertia
        ixx="2.357070580464E-05"
        ixy="-1.01813691701127E-09"
        ixz="2.17579681215238E-08"
        iyy="4.29479133591134E-06"
        iyz="-8.85791114048226E-10"
        izz="2.21058141232446E-05" />
    </inertial>
    <visual>
      <origin
        xyz="0 0 0"
        rpy="0 0 0" />
      <geometry>
        <mesh
          filename="package://lidarcam/meshes/fcam.STL" />
      </geometry>
      <material
        name="">
        <color
          rgba="0.792156862745098 0.819607843137255 0.933333333333333 1" />
      </material>
    </visual>
    <collision>
      <origin
        xyz="0 0 0"
        rpy="0 0 0" />
      <geometry>
        <mesh
          filename="package://lidarcam/meshes/fcam.STL" />
      </geometry>
    </collision>
  </link>
  <joint
    name="fcam"
    type="fixed">
    <origin
      xyz="0.10801 0.012 0.15299"
      rpy="0 0 -1.5708" />
    <parent
      link="base_link" />
    <child
      link="fcam" />
    <axis
      xyz="0 0 0" />
  </joint>
  <link
    name="bcam">
    <inertial>
      <origin
        xyz="0.000445525343312589 -1.10630004970108E-05 0.00129821972548672"
        rpy="0 0 0" />
      <mass
        value="0.0436119949785285" />
      <inertia
        ixx="2.35707056099599E-05"
        ixy="-1.01834758014122E-09"
        ixz="2.17579332532655E-08"
        iyy="4.29479078276668E-06"
        iyz="-8.85484503922049E-10"
        izz="2.21058144654637E-05" />
    </inertial>
    <visual>
      <origin
        xyz="0 0 0"
        rpy="0 0 0" />
      <geometry>
        <mesh
          filename="package://lidarcam/meshes/bcam.STL" />
      </geometry>
      <material
        name="">
        <color
          rgba="0.792156862745098 0.819607843137255 0.933333333333333 1" />
      </material>
    </visual>
    <collision>
      <origin
        xyz="0 0 0"
        rpy="0 0 0" />
      <geometry>
        <mesh
          filename="package://lidarcam/meshes/bcam.STL" />
      </geometry>
    </collision>
  </link>
  <joint
    name="bcam"
    type="fixed">
    <origin
      xyz="0.10801 0.019081 0.11771"
      rpy="0 0.7854 -1.5708" />
    <parent
      link="base_link" />
    <child
      link="bcam" />
    <axis
      xyz="0 0 0" />
  </joint>
  <link
    name="Lidar">
    <inertial>
      <origin
        xyz="0.0135233599432968 0.000461956324468174 -0.0287648857835382"
        rpy="0 0 0" />
      <mass
        value="0.0730845705100255" />
      <inertia
        ixx="1.95808756865045E-05"
        ixy="-1.03933590325011E-07"
        ixz="-4.28391191299091E-07"
        iyy="2.41250079547575E-05"
        iyz="9.4270820064326E-09"
        izz="4.14184516017992E-05" />
    </inertial>
    <visual>
      <origin
        xyz="0 0 0"
        rpy="0 0 0" />
      <geometry>
        <mesh
          filename="package://lidarcam/meshes/Lidar.STL" />
      </geometry>
      <material
        name="">
        <color
          rgba="0.792156862745098 0.819607843137255 0.933333333333333 1" />
      </material>
    </visual>
    <collision>
      <origin
        xyz="0 0 0"
        rpy="0 0 0" />
      <geometry>
        <mesh
          filename="package://lidarcam/meshes/Lidar.STL" />
      </geometry>
    </collision>
  </link>
  <joint
    name="Lidar"
    type="fixed">
    <origin
      xyz="0.10701 0.19058 0.2245"
      rpy="0 0 -1.5708" />
    <parent
      link="base_link" />
    <child
      link="Lidar" />
    <axis
      xyz="0 0 0" />
  </joint>
</robot>